Workbook

Sheet LMStudio
A1: tablescraper-selected-row href | B1: text-lg | D1: text-muted-foreground | E1: font-medium | F1: font-medium 2 | G1: font-medium 3 | H1: opacity-70 | I1: shadow-sm | J1: shadow-sm 3 | K1: shadow-sm 5 | L1: shadow-sm 6
A2: URL | B2: Model | D2: Description | E2: Number of Downloads | F2: Stars | G2: Box | H2: Updates
A3: https://lmstudio.ai/models/nemotron-3-omni | B3: Nemotron 3 Omni | C3: =VLOOKUP(B3,'Unique LMStudio'!A$4:G1001,4,false) | D3: NVIDIA Nemotron 3 Nano Omni is an open multimodal model with highest efficiency that powers sub-agents to complete tasks faster across vision, audio, and language | E3: 32.9K | F3: 7 | H3: Updated 2 days ago | I3: 30B
A4: https://lmstudio.ai/models/qwen3.6 | B4: Qwen3.6 | C4: =VLOOKUP(B4,'Unique LMStudio'!A$4:G1001,4,false) -> https://llm-stats.com/models/qwen3.6-plus | D4: Qwen3.6 prioritizes stability and real-world utility, offering developers a more intuitive, responsive, and genuinely productive coding experience. | E4: 763.3K | F4: 45 | G4: 2 | H4: Updated 2 days ago | I4: 27B | J4: 35B
A5: https://lmstudio.ai/models/gemma-4 | B5: Gemma 4 | C5: =VLOOKUP(B5,'Unique LMStudio'!A$4:G1001,4,false) -> https://llm-stats.com/models/gemma-4-e4b-it | D5: Gemma 4 is Google's most capable family of open models, built from Gemini 3 research. Supports vision input and available in multiple sizes for on-device deployment. | E5: 3.2M | F5: 571 | G5: 4 | H5: Updated 24 days ago | I5: 5.1B | J5: 7.9B | K5: 26B | L5: 31B
A6: https://lmstudio.ai/models/nemotron-3-super | B6: Nemotron 3 Super | C6: =VLOOKUP(B6,'Unique LMStudio'!A$4:G1001,4,false) -> https://llm-stats.com/models/nemotron-3-super-120b-a12b | D6: NVIDIA Nemotron 3 Super, a 120B open hybrid MoE model (12B active), supporting up to 1M tokens context window | E6: 149.3K | F6: 41 | H6: Updated 1 month ago | I6: 120B
A7: https://lmstudio.ai/models/qwen3.5 | B7: Qwen3.5 | C7: =VLOOKUP(B7,'Unique LMStudio'!A$4:G1001,4,false) -> https://llm-stats.com/models/qwen3.5-2b | D7: Qwen3.5 represents a significant leap forward, integrating breakthroughs in multimodal learning, architectural efficiency, reinforcement learning scale, and global accessibility to empower developers and enterprises with unprecedented capability and efficiency | E7: 2.7M | F7: 265 | G7: 5 | H7: Updated 1 month ago | I7: 2B | J7: 4B | K7: 9B | L7: 27B
A8: https://lmstudio.ai/models/lfm2-24b-a2b | B8: LFM2-24B-A2B | C8: =VLOOKUP(B8,'Unique LMStudio'!A$4:G1001,4,false) | D8: LFM2 is a family of hybrid models designed for on-device deployment. LFM2-24B-A2B is the largest model in the family, scaling the architecture to 24 billion parameters while keeping inference efficient. | E8: 76.2K | F8: 15 | H8: Updated 2 months ago | I8: 24B
A9: https://lmstudio.ai/models/qwen3-coder-next | B9: Qwen3-Coder-Next | C9: =VLOOKUP(B9,'Unique LMStudio'!A$4:G1001,4,false) -> https://llm-stats.com/models/qwen3-coder-480b-a35b-instruct | D9: Qwen3 Coder Next is an 80B MoE with 3B active parameters designed for coding agents and local development. Excels at long-horizon reasoning, complex tool usage, and recovery from execution failures. | E9: 272.6K | F9: 77 | H9: Updated 2 months ago | I9: 80B
A10: https://lmstudio.ai/models/glm-4.7 | B10: GLM-4.7 | C10: =VLOOKUP(B10,'Unique LMStudio'!A$4:G1001,4,false) -> https://llm-stats.com/models/glm-4.7 | D10: Open source coding models by Z.ai, based on a new base model and specializing in coding and tool calling. | E10: 307.3K | F10: 105 | H10: Updated 3 months ago | I10: 30B
A11: https://lmstudio.ai/models/functiongemma | B11: FunctionGemma | C11: =VLOOKUP(B11,'Unique LMStudio'!A$4:G1001,4,false) -> https://huggingface.co/google/functiongemma-270m-it | D11: FunctionGemma is a lightweight, open model from Google, built as a foundation for creating your own specialized function calling models. | E11: 2.8K | F11: 44 | H11: Updated 4 months ago | I11: 270M
A12: https://lmstudio.ai/models/nemotron-3 | B12: Nemotron 3 | C12: =VLOOKUP(B12,'Unique LMStudio'!A$4:G1001,4,false) -> https://llm-stats.com/models/nemotron-3-nano-30b-a3b | D12: General purpose reasoning and chat model trained from scratch by NVIDIA. Contains 30B total parameters with only 3.5B active at a time for low-latency MoE inference | E12: 153.3K | F12: 58 | H12: Updated 4 months ago | I12: 30B
A13: https://lmstudio.ai/models/glm-4.6v-flash | B13: GLM-4.6V-Flash | C13: =VLOOKUP(B13,'Unique LMStudio'!A$4:G1001,4,false) -> https://llm-stats.com/models/glm-4.6 | D13: GLM 4.6V Flash is a 9B vision-language model optimized for local deployment and low-latency applications. | E13: 286.4K | F13: 59 | H13: Updated 4 months ago | I13: 9B
A14: https://lmstudio.ai/models/devstral-2 | B14: Devstral 2 | C14: =VLOOKUP(B14,'Unique LMStudio'!A$4:G1001,4,false) -> https://llm-stats.com/models/devstral-small-2507 | D14: Second-generation Devstral for agentic coding. Built for tool use to explore codebases, edit multiple files, and power software engineering agents with newly added vision support. | E14: 183.6K | F14: 60 | G14: 2 | H14: Updated 4 months ago | I14: 24B | J14: 123B
A15: https://lmstudio.ai/models/rnj-1 | B15: Rnj-1 | C15: =VLOOKUP(B15,'Unique LMStudio'!A$4:G1001,4,false) | D15: Rnj-1 is a family of 8B parameter open-weight, dense models trained from scratch by Essential AI. | E15: 63.3K | F15: 19 | H15: Updated 4 months ago | I15: 8B
A16: https://lmstudio.ai/models/ministral | B16: Ministral 3 | C16: =VLOOKUP(B16,'Unique LMStudio'!A$4:G1001,4,false) -> https://llm-stats.com/models/ministral-3-8b-base-2512 | D16: Ministral 3 series, available in three model sizes: 3B, 8B, and 14B parameters. Provides best of class cost-to-performance ratio. | E16: 544.1K | F16: 112 | G16: 6 | H16: Updated 4 months ago | I16: 3B | J16: 3B | K16: 8B | L16: 8B
A17: https://lmstudio.ai/models/qwen3-next | B17: Qwen3 Next | C17: =VLOOKUP(B17,'Unique LMStudio'!A$4:G1001,4,false) -> https://llm-stats.com/models/qwen3-next-80b-a3b-base | D17: Hybrid attention architecture, high-sparsity Mixture-of-Experts 80B model (active 3B). | E17: 57K | F17: 29 | H17: Updated 5 months ago | I17: 80B
A18: https://lmstudio.ai/models/olmo3 | B18: Olmo 3 | C18: =VLOOKUP(B18,'Unique LMStudio'!A$4:G1001,4,false) | D18: Olmo 3 is a family of Open language models designed to enable the science of language models. | E18: 37.8K | F18: 29 | G18: 3 | H18: Updated 5 months ago | I18: 7B | J18: 7B | K18: 32B
A19: https://lmstudio.ai/models/olmocr2 | B19: olmOCR 2 | C19: =VLOOKUP(B19,'Unique LMStudio'!A$4:G1001,4,false) | D19: The olmOCR 2 model is a Vision Language Model (VLM) from Allen AI. | E19: 70.5K | F19: 19 | H19: Updated 5 months ago | I19: 7B
A20: https://lmstudio.ai/models/minimax-m2 | B20: minimax-m2 | C20: =VLOOKUP(B20,'Unique LMStudio'!A$4:G1001,4,false) | D20: MiniMax M2 is a 230B MoE (10B active) model built for coding and agentic workflows | E20: 17.4K | F20: 37 | H20: Updated 5 months ago | I20: 230B
A21: https://lmstudio.ai/models/gpt-oss-safeguard | B21: gpt-oss-safeguard | C21: =VLOOKUP(B21,'Unique LMStudio'!A$4:G1001,4,false) -> https://llm-stats.com/models/gpt-oss-20b | D21: gpt-oss-safeguard-20b and gpt-oss-safeguard-120b are open safety models from OpenAI, building on gpt-oss. Trained to help classify text content based on customizable policies. | E21: 8K | F21: 36 | G21: 2 | H21: Updated 6 months ago | I21: 20B | J21: 120B
A22: https://lmstudio.ai/models/qwen3-vl | B22: Qwen3-VL | C22: =VLOOKUP(B22,'Unique LMStudio'!A$4:G1001,4,false) -> https://llm-stats.com/models/qwen3-vl-4b-instruct | D22: Qwen's latest vision-language model. Includes comprehensive upgrades to visual perception, spatial reasoning, and image understanding. | E22: 763.5K | F22: 128 | G22: 5 | H22: Updated 6 months ago | I22: 2B | J22: 4B | K22: 8B | L22: 30B
A23: https://lmstudio.ai/models/granite-4 | B23: Granite 4.0 | C23: =VLOOKUP(B23,'Unique LMStudio'!A$4:G1001,4,false) | D23: Granite 4.0 language models are lightweight, state-of-the-art open models that natively support multilingual capabilities, coding tasks, RAG, tool use, and JSON output. | E23: 72.4K | F23: 51 | G23: 4 | H23: Updated 6 months ago | I23: 3B | J23: 3B | K23: 7B | L23: 32B
A24: https://lmstudio.ai/models/seed-oss | B24: seed-oss | C24: =VLOOKUP(B24,'Unique LMStudio'!A$4:G1001,4,false) | D24: Advanced reasoning model from ByteDance with flexible "thinking budget" control and ability to reflect on the length of its own reasoning | E24: 54.1K | F24: 23 | H24: Updated 6 months ago | I24: 36B
A25: https://lmstudio.ai/models/qwen3 | B25: Qwen3 | C25: =VLOOKUP(B25,'Unique LMStudio'!A$4:G1001,4,false) -> https://llm-stats.com/models/qwen3-32b | D25: The latest version of the Qwen3 model family, featuring 4B, 30B, and 235B dense and MoE models, both thinking and non-thinking variants. | E25: 480.1K | F25: 178 | G25: 6 | H25: Updated 6 months ago | I25: 4B | J25: 4B | K25: 30B | L25: 30B
A26: https://lmstudio.ai/models/gpt-oss | B26: gpt-oss | C26: =VLOOKUP(B26,'Unique LMStudio'!A$4:G1001,4,false) -> https://llm-stats.com/models/gpt-oss-20b | D26: OpenAI's first open source LLM. Comes in 2 sizes: 20B and 120B. Supports configurable reasoning effort (low, medium, high). Trained for tool use. Apache 2.0 licensed. | E26: 1.7M | F26: 348 | G26: 2 | H26: Updated 6 months ago | I26: 20B | J26: 120B
A27: https://lmstudio.ai/models/qwen3-coder | B27: Qwen3-Coder | C27: =VLOOKUP(B27,'Unique LMStudio'!A$4:G1001,4,false) -> https://llm-stats.com/models/qwen3-coder | D27: State-of-the-art, Mixture-of-Experts local coding model with native support for 256K context length. Available in 30B (3B active) and 480B (35B active) sizes. | E27: 395.3K | F27: 146 | G27: 2 | H27: Updated 6 months ago | I27: 30B | J27: 480B
A28: https://lmstudio.ai/models/ernie-4.5 | B28: Ernie-4.5 | C28: =VLOOKUP(B28,'Unique LMStudio'!A$4:G1001,4,false) | D28: Medium-size Mixture-of-Experts model from Baidu's new Ernie 4.5 line of foundation models. | E28: 21.4K | F28: 12 | H28: Updated 6 months ago | I28: 21B
A29: https://lmstudio.ai/models/lfm2 | B29: LFM2 | C29: =VLOOKUP(B29,'Unique LMStudio'!A$4:G1001,4,false) | D29: LFM2 is a new generation of hybrid models developed by Liquid AI, specifically designed for edge AI and on-device deployment. It sets a new standard in terms of quality, speed, and memory efficiency. | E29: 67.5K | F29: 49 | G29: 3 | H29: Updated 6 months ago | I29: 350M | J29: 700M | K29: 1.2B
A30: https://lmstudio.ai/models/devstral | B30: Devstral | C30: =VLOOKUP(B30,'Unique LMStudio'!A$4:G1001,4,false) -> https://llm-stats.com/models/devstral-small-2507 | D30: Devstral is a coding model from Mistral AI. It excels at using tools to explore codebases, editing multiple files and power software engineering agents. | E30: 78.3K | F30: 40 | G30: 2 | H30: Updated 4 months ago | I30: 23.6B | J30: 24B
A31: https://lmstudio.ai/models/gemma-3n | B31: gemma-3n | C31: =VLOOKUP(B31,'Unique LMStudio'!A$4:G1001,4,false) -> https://llm-stats.com/models/gemma-3n-e2b | D31: Gemma 3n is a generative AI model optimized for use in everyday devices, such as phones, laptops, and tablets. | E31: 250.2K | F31: 95 | G31: 2 | H31: Updated 6 months ago | I31: 4.5B | J31: 6.9B
A32: https://lmstudio.ai/models/mistral-small | B32: Mistral Small | C32: =VLOOKUP(B32,'Unique LMStudio'!A$4:G1001,4,false) -> https://llm-stats.com/models/mistral-small-latest | D32: Mistrall Small is a 'knowledge-dense' 24B multi-modal (image input) local model that supports up to 128 token context length. | E32: 79.6K | F32: 20 | H32: Updated 6 months ago | I32: 24B
A33: https://lmstudio.ai/models/magistral | B33: Magistral | C33: =VLOOKUP(B33,'Unique LMStudio'!A$4:G1001,4,false) -> https://llm-stats.com/models/magistral-small-2506 | D33: MistralAI's open-weight reasoning model. 24B dense transformer model supporting up to 128K token context window. The model is capable of long chains of reasoning traces before providing answers. | E33: 129.9K | F33: 50 | G33: 2 | H33: Updated 6 months ago | I33: 23.6B | J33: 24B
A34: https://lmstudio.ai/models/mistral-nemo | B34: mistral-nemo | C34: =VLOOKUP(B34,'Unique LMStudio'!A$4:G1001,4,false) -> https://llm-stats.com/models/mistral-nemo-instruct-2407 | D34: General purpose dense transformer designed for multilingual use cases. Built in collaboration between MistralAI and NVIDIA. | E34: 46.9K | F34: 9 | H34: Updated 6 months ago | I34: 12B
A35: https://lmstudio.ai/models/qwen2.5-vl | B35: qwen2.5-vl | C35: =VLOOKUP(B35,'Unique LMStudio'!A$4:G1001,4,false) -> https://llm-stats.com/models/qwen2.5-vl-7b | D35: Qwen2.5-VL is a performant vision-language model, capable of recognizing common objects and text. Supports context length of 128k tokens in a variety of human languages. | E35: 195.7K | F35: 30 | G35: 4 | H35: Updated 6 months ago | I35: 3B | J35: 7B | K35: 32B | L35: 72B
A36: https://lmstudio.ai/models/gemma-3 | B36: gemma-3 | C36: =VLOOKUP(B36,'Unique LMStudio'!A$4:G1001,4,false) -> https://llm-stats.com/models/gemma-3-1b-it | D36: State-of-the-art image + text input models from Google, built from the same research and tech used to create the Gemini models | E36: 2.1M | F36: 213 | G36: 5 | H36: Updated 6 months ago | I36: 270M | J36: 1B | K36: 4B | L36: 12B
A37: https://lmstudio.ai/models/phi-4-reasoning | B37: phi-4-reasoning | C37: =VLOOKUP(B37,'Unique LMStudio'!A$4:G1001,4,false) -> https://llm-stats.com/models/phi-4-reasoning | D37: Phi-4-mini-reasoning is a lightweight open model built upon synthetic data with a focus on high-quality, reasoning dense data. | E37: 174.7K | F37: 52 | G37: 3 | H37: Updated 6 months ago | I37: 3.8B | J37: 14.7B | K37: 14.7B
A38: https://lmstudio.ai/models/phi-4 | B38: phi-4 | C38: =VLOOKUP(B38,'Unique LMStudio'!A$4:G1001,4,false) -> https://llm-stats.com/models/phi-4 | D38: phi-4 is a state-of-the-art open model built upon a blend of synthetic datasets, data from filtered public domain websites, and acquired academic books and Q&A datasets. | E38: 36.6K | F38: 18 | G38: 2 | H38: Updated 6 months ago | I38: 3B | J38: 14B
A39: https://lmstudio.ai/models/codestral | B39: Codestral | C39: =VLOOKUP(B39,'Unique LMStudio'!A$4:G1001,4,false) -> https://llm-stats.com/models/codestral-22b | D39: Mistral AI's latest coding model, Codestral can handle both instructions and code completions with ease in over 80 programming languages. | E39: 55.8K | F39: 31 | H39: Updated 6 months ago | I39: 22B
A40: https://lmstudio.ai/models/mistral | B40: Mistral | C40: =VLOOKUP(B40,'Unique LMStudio'!A$4:G1001,4,false) -> https://llm-stats.com/models/mistral-small-latest | D40: One of the most popular open-source LLMs, Mistral's 7B Instruct model's balance of speed, size, and performance makes it a great general-purpose daily driver. | E40: 136.4K | F40: 46 | H40: Updated 6 months ago | I40: 7B
...

Sheet Source Data
A1: https://lmstudio.ai/models
A2: https://openrouter.ai/models?order=latency-low-to-high
A3: https://llm-stats.com/organizations/openai
A4: https://llm-stats.com/organizations
A5: https://magazine.sebastianraschka.com/notes
A6: https://sebastianraschka.com/llm-architecture-gallery/
A7: https://sebastianraschka.com/llm-architecture-gallery/aa-intelligence-index/
A8: https://artificialanalysis.ai/
A10: https://localai.io/getting-started/models/index.html
A11: https://localai.io/gallery.html

Sheet Unique LMStudio
V1: https://docs.z.ai/guides/llm/glm-4.5
S2: https://llm-stats.com/organizations/nvidia | T2: https://llm-stats.com/organizations/qwen | U2: https://llm-stats.com/organizations/google | V2: https://llm-stats.com/organizations/zai-org | W2: https://llm-stats.com/organizations/microsoft | X2: https://llm-stats.com/organizations/mistral | Y2: https://llm-stats.com/organizations/mistral | Z2: https://llm-stats.com/organizations/mistral | AA2: https://llm-stats.com/organizations/deepseek | AB2: https://llm-stats.com/organizations/mistral | AC2: https://llm-stats.com/organizations/mistral | AD2: https://llm-stats.com/organizations/openai | AE2: https://www.together.ai/models/lfm2-24b-a2b | AF2: https://huggingface.co/EssentialAI/rnj-1 | AG2: https://allenai.org/blog/olmo3 | AH2: https://olmocr.allenai.org/ | AI2: https://huggingface.co/MiniMaxAI/MiniMax-M2 | AJ2: https://ernie.baidu.com/ | AK2: https://github.com/ByteDance-Seed/seed-oss | AL2: https://www.ibm.com/granite/docs/models/granite
B3: Reason | C3: Use | I3: http://127.0.0.1:1234/v1/models | Q3: Model | R3: Model | S3: Nemotron | T3: Qwen | U3: Gemma | V3: GLM | W3: Phi | X3: Mistral | Y3: Codestral | Z3: Magistral | AA3: Deepseek | AB3: Devstral | AC3: Ministral | AD3: GPT
A4: =O4 -> Nemotron 3 Omni | E4: GB Size in LMStudio | F4: =VLOOKUP($D4,'LLM Stats list of Model'!$B$2:$N1003,4,false) -> #N/A | G4: =VLOOKUP($D4,'LLM Stats list of Model'!$B$2:$N1003,6,false) -> #N/A | H4: =R4 -> Nemotron | L4: =IFERROR(__xludf.DUMMYFUNCTION("QUERY( ARRAYFORMULA(REGEXEXTRACT(LMStudio!B3:B1003, ""^[^ ]+"")), ""select Col1, count(Col1) where Col1 is not null group by Col1 label count(Col1) ''"" )"),"#N/A") -> #N/A | M4: =IFERROR(__xludf.DUMMYFUNCTION("""COMPUTED_VALUE"""),959.0) -> 959 | O4: {=UNIQUE(LMStudio!B3:B1003)} -> Nemotron 3 Omni | P4: =IFERROR(__xludf.DUMMYFUNCTION("ARRAYFORMULA( IF(O4:O1003="""","""", IF(REGEXMATCH(O4:O1003,""(?i)gemma""),""Gemma"", IF(REGEXMATCH(O4:O1003,""(?i)qwen""),""Qwen"", IF(REGEXMATCH(O4:O1003,""(?i)nemotron""),""Nemotron"", ""Other"")))) )"),"Nemotron") -> Nemotron | Q4: {=IF(S4:S1003="","", IF(S4:S1003<>"Other", S4:S1003, IF(T4:T1003<>"Other", T4:T1003, "Other") ) )} -> Nemotron | R4: =IFERROR(__xludf.DUMMYFUNCTION("ARRAYFORMULA( IF(S4:S1003="""","""", IFERROR( BYROW(S4:AAL1003, LAMBDA(r, INDEX(FILTER(r, r<>""Other""), 1)) ), ""Other"" ) ) )"),"Nemotron") -> Nemotron | S4: =IFERROR(__xludf.DUMMYFUNCTION("ARRAYFORMULA( IF($O4:$O1003="""","""", IF(REGEXMATCH($O4:$O1003,""(?i)""&S$3), S$3, ""Other"") ) )"),"Nemotron") -> Nemotron | T4: =IFERROR(__xludf.DUMMYFUNCTION("ARRAYFORMULA( IF($O4:$O1003="""","""", IF(REGEXMATCH($O4:$O1003,""(?i)""&T$3), T$3, ""Other"") ) )"),"Other") -> Other | U4: =IFERROR(__xludf.DUMMYFUNCTION("ARRAYFORMULA( IF($O4:$O1003="""","""", IF(REGEXMATCH($O4:$O1003,""(?i)""&U$3), U$3, ""Other"") ) )"),"Other") -> Other | V4: =IFERROR(__xludf.DUMMYFUNCTION("ARRAYFORMULA( IF($O4:$O1003="""","""", IF(REGEXMATCH($O4:$O1003,""(?i)""&V$3), V$3, ""Other"") ) )"),"Other") -> Other | W4: =IFERROR(__xludf.DUMMYFUNCTION("ARRAYFORMULA( IF($O4:$O1003="""","""", IF(REGEXMATCH($O4:$O1003,""(?i)""&W$3), W$3, ""Other"") ) )"),"Other") -> Other | X4: =IFERROR(__xludf.DUMMYFUNCTION("ARRAYFORMULA( IF($O4:$O1003="""","""", IF(REGEXMATCH($O4:$O1003,""(?i)""&X$3), X$3, ""Other"") ) )"),"Other") -> Other | Y4: =IFERROR(__xludf.DUMMYFUNCTION("ARRAYFORMULA( IF($O4:$O1003="""","""", IF(REGEXMATCH($O4:$O1003,""(?i)""&Y$3), Y$3, ""Other"") ) )"),"Other") -> Other | Z4: =IFERROR(__xludf.DUMMYFUNCTION("ARRAYFORMULA( IF($O4:$O1003="""","""", IF(REGEXMATCH($O4:$O1003,""(?i)""&Z$3), Z$3, ""Other"") ) )"),"Other") -> Other | AA4: =IFERROR(__xludf.DUMMYFUNCTION("ARRAYFORMULA( IF($O4:$O1003="""","""", IF(REGEXMATCH($O4:$O1003,""(?i)""&AA$3), AA$3, ""Other"") ) )"),"Other") -> Other | AB4: =IFERROR(__xludf.DUMMYFUNCTION("ARRAYFORMULA( IF($O4:$O1003="""","""", IF(REGEXMATCH($O4:$O1003,""(?i)""&AB$3), AB$3, ""Other"") ) )"),"Other") -> Other | AC4: =IFERROR(__xludf.DUMMYFUNCTION("ARRAYFORMULA( IF($O4:$O1003="""","""", IF(REGEXMATCH($O4:$O1003,""(?i)""&AC$3), AC$3, ""Other"") ) )"),"Other") -> Other | AD4: =IFERROR(__xludf.DUMMYFUNCTION("ARRAYFORMULA( IF($O4:$O1003="""","""", IF(REGEXMATCH($O4:$O1003,""(?i)""&AD$3), AD$3, ""Other"") ) )"),"Other") -> Other
A5: =O5 -> Qwen3.6 | D5: https://llm-stats.com/models/qwen3.6-plus | F5: =VLOOKUP($D5,'LLM Stats list of Model'!$B$2:$N1003,4,false) -> 2 | G5: =VLOOKUP($D5,'LLM Stats list of Model'!$B$2:$N1003,6,false) -> Qwen3.6 Plus | H5: =R5 -> Qwen | I5: =VLOOKUP(H5,'Unique Organization'!C$2:D$13,2,FALSE) -> qwen | L5: =IFERROR(__xludf.DUMMYFUNCTION("""COMPUTED_VALUE"""),"Codestral") -> Codestral | M5: =IFERROR(__xludf.DUMMYFUNCTION("""COMPUTED_VALUE"""),1.0) -> 1 | O5: Qwen3.6 | P5: =IFERROR(__xludf.DUMMYFUNCTION("""COMPUTED_VALUE"""),"Qwen") -> Qwen | Q5: Qwen | R5: =IFERROR(__xludf.DUMMYFUNCTION("""COMPUTED_VALUE"""),"Qwen") -> Qwen | S5: =IFERROR(__xludf.DUMMYFUNCTION("""COMPUTED_VALUE"""),"Other") -> Other | T5: =IFERROR(__xludf.DUMMYFUNCTION("""COMPUTED_VALUE"""),"Qwen") -> Qwen | U5: =IFERROR(__xludf.DUMMYFUNCTION("""COMPUTED_VALUE"""),"Other") -> Other | V5: =IFERROR(__xludf.DUMMYFUNCTION("""COMPUTED_VALUE"""),"Other") -> Other | W5: =IFERROR(__xludf.DUMMYFUNCTION("""COMPUTED_VALUE"""),"Other") -> Other | X5: =IFERROR(__xludf.DUMMYFUNCTION("""COMPUTED_VALUE"""),"Other") -> Other | Y5: =IFERROR(__xludf.DUMMYFUNCTION("""COMPUTED_VALUE"""),"Other") -> Other | Z5: =IFERROR(__xludf.DUMMYFUNCTION("""COMPUTED_VALUE"""),"Other") -> Other | AA5: =IFERROR(__xludf.DUMMYFUNCTION("""COMPUTED_VALUE"""),"Other") -> Other | AB5: =IFERROR(__xludf.DUMMYFUNCTION("""COMPUTED_VALUE"""),"Other") -> Other | ... AD5: =IFERROR(__xludf.DUMMYFUNCTION("""COMPUTED_VALUE"""),"Other") -> Other
A6: =O6 -> Gemma 4 | D6: https://llm-stats.com/models/gemma-4-e4b-it | F6: =VLOOKUP($D6,'LLM Stats list of Model'!$B$2:$N1003,4,false) | G6: =VLOOKUP($D6,'LLM Stats list of Model'!$B$2:$N1003,6,false) -> Gemma 4 E4B | H6: =R6 -> Gemma | I6: =VLOOKUP(H6,'Unique Organization'!C$2:D$13,2,FALSE) -> google | L6: =IFERROR(__xludf.DUMMYFUNCTION("""COMPUTED_VALUE"""),"Devstral") -> Devstral | M6: =IFERROR(__xludf.DUMMYFUNCTION("""COMPUTED_VALUE"""),2.0) -> 2 | O6: Gemma 4 | P6: =IFERROR(__xludf.DUMMYFUNCTION("""COMPUTED_VALUE"""),"Gemma") -> Gemma | Q6: Other | R6: =IFERROR(__xludf.DUMMYFUNCTION("""COMPUTED_VALUE"""),"Gemma") -> Gemma | S6: =IFERROR(__xludf.DUMMYFUNCTION("""COMPUTED_VALUE"""),"Other") -> Other | T6: =IFERROR(__xludf.DUMMYFUNCTION("""COMPUTED_VALUE"""),"Other") -> Other | U6: =IFERROR(__xludf.DUMMYFUNCTION("""COMPUTED_VALUE"""),"Gemma") -> Gemma | V6: =IFERROR(__xludf.DUMMYFUNCTION("""COMPUTED_VALUE"""),"Other") -> Other | W6: =IFERROR(__xludf.DUMMYFUNCTION("""COMPUTED_VALUE"""),"Other") -> Other | X6: =IFERROR(__xludf.DUMMYFUNCTION("""COMPUTED_VALUE"""),"Other") -> Other | Y6: =IFERROR(__xludf.DUMMYFUNCTION("""COMPUTED_VALUE"""),"Other") -> Other | Z6: =IFERROR(__xludf.DUMMYFUNCTION("""COMPUTED_VALUE"""),"Other") -> Other | AA6: =IFERROR(__xludf.DUMMYFUNCTION("""COMPUTED_VALUE"""),"Other") -> Other | AB6: =IFERROR(__xludf.DUMMYFUNCTION("""COMPUTED_VALUE"""),"Other") -> Other | AC6: =IFERROR(__xludf.DUMMYFUNCTION("""COMPUTED_VALUE"""),"Other") -> Other | AD6: =IFERROR(__xludf.DUMMYFUNCTION("""COMPUTED_VALUE"""),"Other") -> Other
A7: =O7 -> Nemotron 3 Super | D7: https://llm-stats.com/models/nemotron-3-super-120b-a12b | F7: =VLOOKUP($D7,'LLM Stats list of Model'!$B$2:$N1003,4,false) | G7: =VLOOKUP($D7,'LLM Stats list of Model'!$B$2:$N1003,6,false) -> Nemotron 3 Super (120B A12B) | H7: =R7 -> Nemotron | I7: =VLOOKUP(H7,'Unique Organization'!C$2:D$13,2,FALSE) -> nvidia | L7: =IFERROR(__xludf.DUMMYFUNCTION("""COMPUTED_VALUE"""),"Ernie-4.5") -> Ernie-4.5 | M7: =IFERROR(__xludf.DUMMYFUNCTION("""COMPUTED_VALUE"""),1.0) -> 1 | O7: Nemotron 3 Super | P7: =IFERROR(__xludf.DUMMYFUNCTION("""COMPUTED_VALUE"""),"Nemotron") -> Nemotron | Q7: Nemotron | R7: =IFERROR(__xludf.DUMMYFUNCTION("""COMPUTED_VALUE"""),"Nemotron") -> Nemotron | S7: =IFERROR(__xludf.DUMMYFUNCTION("""COMPUTED_VALUE"""),"Nemotron") -> Nemotron | T7: =IFERROR(__xludf.DUMMYFUNCTION("""COMPUTED_VALUE"""),"Other") -> Other | U7: =IFERROR(__xludf.DUMMYFUNCTION("""COMPUTED_VALUE"""),"Other") -> Other | V7: =IFERROR(__xludf.DUMMYFUNCTION("""COMPUTED_VALUE"""),"Other") -> Other | W7: =IFERROR(__xludf.DUMMYFUNCTION("""COMPUTED_VALUE"""),"Other") -> Other | X7: =IFERROR(__xludf.DUMMYFUNCTION("""COMPUTED_VALUE"""),"Other") -> Other | Y7: =IFERROR(__xludf.DUMMYFUNCTION("""COMPUTED_VALUE"""),"Other") -> Other | Z7: =IFERROR(__xludf.DUMMYFUNCTION("""COMPUTED_VALUE"""),"Other") -> Other | AA7: =IFERROR(__xludf.DUMMYFUNCTION("""COMPUTED_VALUE"""),"Other") -> Other | ... AD7: =IFERROR(__xludf.DUMMYFUNCTION("""COMPUTED_VALUE"""),"Other") -> Other
A8: =O8 -> Qwen3.5 | D8: https://llm-stats.com/models/qwen3.5-2b | F8: =VLOOKUP($D8,'LLM Stats list of Model'!$B$2:$N1003,4,false) -> 2 | G8: =VLOOKUP($D8,'LLM Stats list of Model'!$B$2:$N1003,6,false) -> Qwen3.5-2B | H8: =R8 -> Qwen | I8: =VLOOKUP(H8,'Unique Organization'!C$2:D$13,2,FALSE) -> qwen | L8: =IFERROR(__xludf.DUMMYFUNCTION("""COMPUTED_VALUE"""),"FunctionGemma") -> FunctionGemma | M8: =IFERROR(__xludf.DUMMYFUNCTION("""COMPUTED_VALUE"""),1.0) -> 1 | O8: Qwen3.5 | P8: =IFERROR(__xludf.DUMMYFUNCTION("""COMPUTED_VALUE"""),"Qwen") -> Qwen | Q8: Qwen | R8: =IFERROR(__xludf.DUMMYFUNCTION("""COMPUTED_VALUE"""),"Qwen") -> Qwen | S8: =IFERROR(__xludf.DUMMYFUNCTION("""COMPUTED_VALUE"""),"Other") -> Other | T8: =IFERROR(__xludf.DUMMYFUNCTION("""COMPUTED_VALUE"""),"Qwen") -> Qwen | U8: =IFERROR(__xludf.DUMMYFUNCTION("""COMPUTED_VALUE"""),"Other") -> Other | V8: =IFERROR(__xludf.DUMMYFUNCTION("""COMPUTED_VALUE"""),"Other") -> Other | W8: =IFERROR(__xludf.DUMMYFUNCTION("""COMPUTED_VALUE"""),"Other") -> Other | X8: =IFERROR(__xludf.DUMMYFUNCTION("""COMPUTED_VALUE"""),"Other") -> Other | Y8: =IFERROR(__xludf.DUMMYFUNCTION("""COMPUTED_VALUE"""),"Other") -> Other | Z8: =IFERROR(__xludf.DUMMYFUNCTION("""COMPUTED_VALUE"""),"Other") -> Other | AA8: =IFERROR(__xludf.DUMMYFUNCTION("""COMPUTED_VALUE"""),"Other") -> Other | AB8: =IFERROR(__xludf.DUMMYFUNCTION("""COMPUTED_VALUE"""),"Other") -> Other | ... AD8: =IFERROR(__xludf.DUMMYFUNCTION("""COMPUTED_VALUE"""),"Other") -> Other
A9: =O9 -> LFM2-24B-A2B | L9: =IFERROR(__xludf.DUMMYFUNCTION("""COMPUTED_VALUE"""),"GLM-4.6V-Flash") -> GLM-4.6V-Flash | M9: =IFERROR(__xludf.DUMMYFUNCTION("""COMPUTED_VALUE"""),1.0) -> 1 | O9: LFM2-24B-A2B | P9: =IFERROR(__xludf.DUMMYFUNCTION("""COMPUTED_VALUE"""),"Other") -> Other | Q9: Other | S9: =IFERROR(__xludf.DUMMYFUNCTION("""COMPUTED_VALUE"""),"Other") -> Other | T9: =IFERROR(__xludf.DUMMYFUNCTION("""COMPUTED_VALUE"""),"Other") -> Other | U9: =IFERROR(__xludf.DUMMYFUNCTION("""COMPUTED_VALUE"""),"Other") -> Other | V9: =IFERROR(__xludf.DUMMYFUNCTION("""COMPUTED_VALUE"""),"Other") -> Other | W9: =IFERROR(__xludf.DUMMYFUNCTION("""COMPUTED_VALUE"""),"Other") -> Other | X9: =IFERROR(__xludf.DUMMYFUNCTION("""COMPUTED_VALUE"""),"Other") -> Other | Y9: =IFERROR(__xludf.DUMMYFUNCTION("""COMPUTED_VALUE"""),"Other") -> Other | Z9: =IFERROR(__xludf.DUMMYFUNCTION("""COMPUTED_VALUE"""),"Other") -> Other | ... AD9: =IFERROR(__xludf.DUMMYFUNCTION("""COMPUTED_VALUE"""),"Other") -> Other
A10: =O10 -> Qwen3-Coder-Next | D10: https://llm-stats.com/models/qwen3-coder-480b-a35b-instruct | F10: =VLOOKUP($D10,'LLM Stats list of Model'!$B$2:$N1003,4,false) -> 2 | G10: =VLOOKUP($D10,'LLM Stats list of Model'!$B$2:$N1003,6,false) -> Qwen3-Coder 480B A35B Instruct | H10: =R10 -> Qwen | I10: =VLOOKUP(H10,'Unique Organization'!C$2:D$13,2,FALSE) -> qwen | L10: =IFERROR(__xludf.DUMMYFUNCTION("""COMPUTED_VALUE"""),"GLM-4.7") -> GLM-4.7 | M10: =IFERROR(__xludf.DUMMYFUNCTION("""COMPUTED_VALUE"""),1.0) -> 1 | O10: Qwen3-Coder-Next | P10: =IFERROR(__xludf.DUMMYFUNCTION("""COMPUTED_VALUE"""),"Qwen") -> Qwen | Q10: Qwen | R10: =IFERROR(__xludf.DUMMYFUNCTION("""COMPUTED_VALUE"""),"Qwen") -> Qwen | S10: =IFERROR(__xludf.DUMMYFUNCTION("""COMPUTED_VALUE"""),"Other") -> Other | T10: =IFERROR(__xludf.DUMMYFUNCTION("""COMPUTED_VALUE"""),"Qwen") -> Qwen | U10: =IFERROR(__xludf.DUMMYFUNCTION("""COMPUTED_VALUE"""),"Other") -> Other | V10: =IFERROR(__xludf.DUMMYFUNCTION("""COMPUTED_VALUE"""),"Other") -> Other | W10: =IFERROR(__xludf.DUMMYFUNCTION("""COMPUTED_VALUE"""),"Other") -> Other | X10: =IFERROR(__xludf.DUMMYFUNCTION("""COMPUTED_VALUE"""),"Other") -> Other | Y10: =IFERROR(__xludf.DUMMYFUNCTION("""COMPUTED_VALUE"""),"Other") -> Other | Z10: =IFERROR(__xludf.DUMMYFUNCTION("""COMPUTED_VALUE"""),"Other") -> Other | AA10: =IFERROR(__xludf.DUMMYFUNCTION("""COMPUTED_VALUE"""),"Other") -> Other | AB10: =IFERROR(__xludf.DUMMYFUNCTION("""COMPUTED_VALUE"""),"Other") -> Other | ... AD10: =IFERROR(__xludf.DUMMYFUNCTION("""COMPUTED_VALUE"""),"Other") -> Other
A11: =O11 -> GLM-4.7 | D11: https://llm-stats.com/models/glm-4.7 | F11: =VLOOKUP($D11,'LLM Stats list of Model'!$B$2:$N1003,4,false) | G11: =VLOOKUP($D11,'LLM Stats list of Model'!$B$2:$N1003,6,false) -> GLM-4.7 | H11: =R11 -> GLM | I11: =VLOOKUP(H11,'Unique Organization'!C$2:D$13,2,FALSE) -> zai-org | L11: =IFERROR(__xludf.DUMMYFUNCTION("""COMPUTED_VALUE"""),"Gemma") -> Gemma | M11: =IFERROR(__xludf.DUMMYFUNCTION("""COMPUTED_VALUE"""),1.0) -> 1 | O11: GLM-4.7 | P11: =IFERROR(__xludf.DUMMYFUNCTION("""COMPUTED_VALUE"""),"Other") -> Other | Q11: Other | R11: =IFERROR(__xludf.DUMMYFUNCTION("""COMPUTED_VALUE"""),"GLM") -> GLM | S11: =IFERROR(__xludf.DUMMYFUNCTION("""COMPUTED_VALUE"""),"Other") -> Other | T11: =IFERROR(__xludf.DUMMYFUNCTION("""COMPUTED_VALUE"""),"Other") -> Other | U11: =IFERROR(__xludf.DUMMYFUNCTION("""COMPUTED_VALUE"""),"Other") -> Other | V11: =IFERROR(__xludf.DUMMYFUNCTION("""COMPUTED_VALUE"""),"GLM") -> GLM | W11: =IFERROR(__xludf.DUMMYFUNCTION("""COMPUTED_VALUE"""),"Other") -> Other | X11: =IFERROR(__xludf.DUMMYFUNCTION("""COMPUTED_VALUE"""),"Other") -> Other | Y11: =IFERROR(__xludf.DUMMYFUNCTION("""COMPUTED_VALUE"""),"Other") -> Other | Z11: =IFERROR(__xludf.DUMMYFUNCTION("""COMPUTED_VALUE"""),"Other") -> Other | AA11: =IFERROR(__xludf.DUMMYFUNCTION("""COMPUTED_VALUE"""),"Other") -> Other | AB11: =IFERROR(__xludf.DUMMYFUNCTION("""COMPUTED_VALUE"""),"Other") -> Other | AC11: =IFERROR(__xludf.DUMMYFUNCTION("""COMPUTED_VALUE"""),"Other") -> Other | AD11: =IFERROR(__xludf.DUMMYFUNCTION("""COMPUTED_VALUE"""),"Other") -> Other
A12: =O12 -> FunctionGemma | D12: https://huggingface.co/google/functiongemma-270m-it | H12: =R12 -> Gemma | I12: =VLOOKUP(H12,'Unique Organization'!C$2:D$13,2,FALSE) -> google | L12: =IFERROR(__xludf.DUMMYFUNCTION("""COMPUTED_VALUE"""),"Granite") -> Granite | M12: =IFERROR(__xludf.DUMMYFUNCTION("""COMPUTED_VALUE"""),1.0) -> 1 | O12: FunctionGemma | P12: =IFERROR(__xludf.DUMMYFUNCTION("""COMPUTED_VALUE"""),"Gemma") -> Gemma | Q12: Other | R12: =IFERROR(__xludf.DUMMYFUNCTION("""COMPUTED_VALUE"""),"Gemma") -> Gemma | S12: =IFERROR(__xludf.DUMMYFUNCTION("""COMPUTED_VALUE"""),"Other") -> Other | T12: =IFERROR(__xludf.DUMMYFUNCTION("""COMPUTED_VALUE"""),"Other") -> Other | U12: =IFERROR(__xludf.DUMMYFUNCTION("""COMPUTED_VALUE"""),"Gemma") -> Gemma | V12: =IFERROR(__xludf.DUMMYFUNCTION("""COMPUTED_VALUE"""),"Other") -> Other | W12: =IFERROR(__xludf.DUMMYFUNCTION("""COMPUTED_VALUE"""),"Other") -> Other | X12: =IFERROR(__xludf.DUMMYFUNCTION("""COMPUTED_VALUE"""),"Other") -> Other | Y12: =IFERROR(__xludf.DUMMYFUNCTION("""COMPUTED_VALUE"""),"Other") -> Other | Z12: =IFERROR(__xludf.DUMMYFUNCTION("""COMPUTED_VALUE"""),"Other") -> Other | AA12: =IFERROR(__xludf.DUMMYFUNCTION("""COMPUTED_VALUE"""),"Other") -> Other | AB12: =IFERROR(__xludf.DUMMYFUNCTION("""COMPUTED_VALUE"""),"Other") -> Other | AC12: =IFERROR(__xludf.DUMMYFUNCTION("""COMPUTED_VALUE"""),"Other") -> Other | AD12: =IFERROR(__xludf.DUMMYFUNCTION("""COMPUTED_VALUE"""),"Other") -> Other
A13: =O13 -> Nemotron 3 | D13: https://llm-stats.com/models/nemotron-3-nano-30b-a3b | F13: =VLOOKUP($D13,'LLM Stats list of Model'!$B$2:$N1003,4,false) | G13: =VLOOKUP($D13,'LLM Stats list of Model'!$B$2:$N1003,6,false) -> Nemotron 3 Nano (30B A3B) | H13: =R13 -> Nemotron | I13: =VLOOKUP(H13,'Unique Organization'!C$2:D$13,2,FALSE) -> nvidia | L13: =IFERROR(__xludf.DUMMYFUNCTION("""COMPUTED_VALUE"""),"LFM2") -> LFM2 | M13: =IFERROR(__xludf.DUMMYFUNCTION("""COMPUTED_VALUE"""),1.0) -> 1 | O13: Nemotron 3 | P13: =IFERROR(__xludf.DUMMYFUNCTION("""COMPUTED_VALUE"""),"Nemotron") -> Nemotron | Q13: Nemotron | R13: =IFERROR(__xludf.DUMMYFUNCTION("""COMPUTED_VALUE"""),"Nemotron") -> Nemotron | S13: =IFERROR(__xludf.DUMMYFUNCTION("""COMPUTED_VALUE"""),"Nemotron") -> Nemotron | T13: =IFERROR(__xludf.DUMMYFUNCTION("""COMPUTED_VALUE"""),"Other") -> Other | U13: =IFERROR(__xludf.DUMMYFUNCTION("""COMPUTED_VALUE"""),"Other") -> Other | V13: =IFERROR(__xludf.DUMMYFUNCTION("""COMPUTED_VALUE"""),"Other") -> Other | W13: =IFERROR(__xludf.DUMMYFUNCTION("""COMPUTED_VALUE"""),"Other") -> Other | X13: =IFERROR(__xludf.DUMMYFUNCTION("""COMPUTED_VALUE"""),"Other") -> Other | Y13: =IFERROR(__xludf.DUMMYFUNCTION("""COMPUTED_VALUE"""),"Other") -> Other | Z13: =IFERROR(__xludf.DUMMYFUNCTION("""COMPUTED_VALUE"""),"Other") -> Other | AA13: =IFERROR(__xludf.DUMMYFUNCTION("""COMPUTED_VALUE"""),"Other") -> Other | ... AD13: =IFERROR(__xludf.DUMMYFUNCTION("""COMPUTED_VALUE"""),"Other") -> Other
A14: =O14 -> GLM-4.6V-Flash | D14: https://llm-stats.com/models/glm-4.6 | F14: =VLOOKUP($D14,'LLM Stats list of Model'!$B$2:$N1003,4,false) | G14: =VLOOKUP($D14,'LLM Stats list of Model'!$B$2:$N1003,6,false) -> GLM-4.6 | H14: =R14 -> GLM | I14: =VLOOKUP(H14,'Unique Organization'!C$2:D$13,2,FALSE) -> zai-org | L14: =IFERROR(__xludf.DUMMYFUNCTION("""COMPUTED_VALUE"""),"LFM2-24B-A2B") -> LFM2-24B-A2B | M14: =IFERROR(__xludf.DUMMYFUNCTION("""COMPUTED_VALUE"""),1.0) -> 1 | O14: GLM-4.6V-Flash | P14: =IFERROR(__xludf.DUMMYFUNCTION("""COMPUTED_VALUE"""),"Other") -> Other | Q14: Other | R14: =IFERROR(__xludf.DUMMYFUNCTION("""COMPUTED_VALUE"""),"GLM") -> GLM | S14: =IFERROR(__xludf.DUMMYFUNCTION("""COMPUTED_VALUE"""),"Other") -> Other | T14: =IFERROR(__xludf.DUMMYFUNCTION("""COMPUTED_VALUE"""),"Other") -> Other | U14: =IFERROR(__xludf.DUMMYFUNCTION("""COMPUTED_VALUE"""),"Other") -> Other | V14: =IFERROR(__xludf.DUMMYFUNCTION("""COMPUTED_VALUE"""),"GLM") -> GLM | W14: =IFERROR(__xludf.DUMMYFUNCTION("""COMPUTED_VALUE"""),"Other") -> Other | X14: =IFERROR(__xludf.DUMMYFUNCTION("""COMPUTED_VALUE"""),"Other") -> Other | Y14: =IFERROR(__xludf.DUMMYFUNCTION("""COMPUTED_VALUE"""),"Other") -> Other | Z14: =IFERROR(__xludf.DUMMYFUNCTION("""COMPUTED_VALUE"""),"Other") -> Other | AA14: =IFERROR(__xludf.DUMMYFUNCTION("""COMPUTED_VALUE"""),"Other") -> Other | AB14: =IFERROR(__xludf.DUMMYFUNCTION("""COMPUTED_VALUE"""),"Other") -> Other | AC14: =IFERROR(__xludf.DUMMYFUNCTION("""COMPUTED_VALUE"""),"Other") -> Other | AD14: =IFERROR(__xludf.DUMMYFUNCTION("""COMPUTED_VALUE"""),"Other") -> Other
A15: =O15 -> Devstral 2 | D15: https://llm-stats.com/models/devstral-small-2507 | F15: =VLOOKUP($D15,'LLM Stats list of Model'!$B$2:$N1003,4,false) | G15: =VLOOKUP($D15,'LLM Stats list of Model'!$B$2:$N1003,6,false) -> Devstral Small 1.1 | H15: =R15 -> Devstral | I15: =VLOOKUP(H15,'Unique Organization'!C$2:D$13,2,FALSE) -> mistral | L15: =IFERROR(__xludf.DUMMYFUNCTION("""COMPUTED_VALUE"""),"Magistral") -> Magistral | M15: =IFERROR(__xludf.DUMMYFUNCTION("""COMPUTED_VALUE"""),1.0) -> 1 | O15: Devstral 2 | P15: =IFERROR(__xludf.DUMMYFUNCTION("""COMPUTED_VALUE"""),"Other") -> Other | Q15: Other | R15: =IFERROR(__xludf.DUMMYFUNCTION("""COMPUTED_VALUE"""),"Devstral") -> Devstral | S15: =IFERROR(__xludf.DUMMYFUNCTION("""COMPUTED_VALUE"""),"Other") -> Other | T15: =IFERROR(__xludf.DUMMYFUNCTION("""COMPUTED_VALUE"""),"Other") -> Other | U15: =IFERROR(__xludf.DUMMYFUNCTION("""COMPUTED_VALUE"""),"Other") -> Other | V15: =IFERROR(__xludf.DUMMYFUNCTION("""COMPUTED_VALUE"""),"Other") -> Other | W15: =IFERROR(__xludf.DUMMYFUNCTION("""COMPUTED_VALUE"""),"Other") -> Other | X15: =IFERROR(__xludf.DUMMYFUNCTION("""COMPUTED_VALUE"""),"Other") -> Other | Y15: =IFERROR(__xludf.DUMMYFUNCTION("""COMPUTED_VALUE"""),"Other") -> Other | Z15: =IFERROR(__xludf.DUMMYFUNCTION("""COMPUTED_VALUE"""),"Other") -> Other | AA15: =IFERROR(__xludf.DUMMYFUNCTION("""COMPUTED_VALUE"""),"Other") -> Other | AB15: =IFERROR(__xludf.DUMMYFUNCTION("""COMPUTED_VALUE"""),"Devstral") -> Devstral | AC15: =IFERROR(__xludf.DUMMYFUNCTION("""COMPUTED_VALUE"""),"Other") -> Other | AD15: =IFERROR(__xludf.DUMMYFUNCTION("""COMPUTED_VALUE"""),"Other") -> Other
A16: =O16 -> Rnj-1 | L16: =IFERROR(__xludf.DUMMYFUNCTION("""COMPUTED_VALUE"""),"Ministral") -> Ministral | M16: =IFERROR(__xludf.DUMMYFUNCTION("""COMPUTED_VALUE"""),1.0) -> 1 | O16: Rnj-1 | P16: =IFERROR(__xludf.DUMMYFUNCTION("""COMPUTED_VALUE"""),"Other") -> Other | Q16: Other | S16: =IFERROR(__xludf.DUMMYFUNCTION("""COMPUTED_VALUE"""),"Other") -> Other | T16: =IFERROR(__xludf.DUMMYFUNCTION("""COMPUTED_VALUE"""),"Other") -> Other | U16: =IFERROR(__xludf.DUMMYFUNCTION("""COMPUTED_VALUE"""),"Other") -> Other | V16: =IFERROR(__xludf.DUMMYFUNCTION("""COMPUTED_VALUE"""),"Other") -> Other | W16: =IFERROR(__xludf.DUMMYFUNCTION("""COMPUTED_VALUE"""),"Other") -> Other | X16: =IFERROR(__xludf.DUMMYFUNCTION("""COMPUTED_VALUE"""),"Other") -> Other | Y16: =IFERROR(__xludf.DUMMYFUNCTION("""COMPUTED_VALUE"""),"Other") -> Other | Z16: =IFERROR(__xludf.DUMMYFUNCTION("""COMPUTED_VALUE"""),"Other") -> Other | ... AD16: =IFERROR(__xludf.DUMMYFUNCTION("""COMPUTED_VALUE"""),"Other") -> Other
A17: =O17 -> Ministral 3 | D17: https://llm-stats.com/models/ministral-3-8b-base-2512 | F17: =VLOOKUP($D17,'LLM Stats list of Model'!$B$2:$N1003,4,false) | G17: =VLOOKUP($D17,'LLM Stats list of Model'!$B$2:$N1003,6,false) -> Ministral 3 (8B Base 2512) | H17: =R17 -> Ministral | I17: =VLOOKUP(H17,'Unique Organization'!C$2:D$13,2,FALSE) -> mistral | L17: =IFERROR(__xludf.DUMMYFUNCTION("""COMPUTED_VALUE"""),"Mistral") -> Mistral | M17: =IFERROR(__xludf.DUMMYFUNCTION("""COMPUTED_VALUE"""),2.0) -> 2 | O17: Ministral 3 | P17: =IFERROR(__xludf.DUMMYFUNCTION("""COMPUTED_VALUE"""),"Other") -> Other | Q17: Other | R17: =IFERROR(__xludf.DUMMYFUNCTION("""COMPUTED_VALUE"""),"Ministral") -> Ministral | S17: =IFERROR(__xludf.DUMMYFUNCTION("""COMPUTED_VALUE"""),"Other") -> Other | T17: =IFERROR(__xludf.DUMMYFUNCTION("""COMPUTED_VALUE"""),"Other") -> Other | U17: =IFERROR(__xludf.DUMMYFUNCTION("""COMPUTED_VALUE"""),"Other") -> Other | V17: =IFERROR(__xludf.DUMMYFUNCTION("""COMPUTED_VALUE"""),"Other") -> Other | W17: =IFERROR(__xludf.DUMMYFUNCTION("""COMPUTED_VALUE"""),"Other") -> Other | X17: =IFERROR(__xludf.DUMMYFUNCTION("""COMPUTED_VALUE"""),"Other") -> Other | Y17: =IFERROR(__xludf.DUMMYFUNCTION("""COMPUTED_VALUE"""),"Other") -> Other | Z17: =IFERROR(__xludf.DUMMYFUNCTION("""COMPUTED_VALUE"""),"Other") -> Other | ... AB17: =IFERROR(__xludf.DUMMYFUNCTION("""COMPUTED_VALUE"""),"Other") -> Other | AC17: =IFERROR(__xludf.DUMMYFUNCTION("""COMPUTED_VALUE"""),"Ministral") -> Ministral | AD17: =IFERROR(__xludf.DUMMYFUNCTION("""COMPUTED_VALUE"""),"Other") -> Other
A18: =O18 -> Qwen3 Next | D18: https://llm-stats.com/models/qwen3-next-80b-a3b-base | F18: =VLOOKUP($D18,'LLM Stats list of Model'!$B$2:$N1003,4,false) -> 2 | G18: =VLOOKUP($D18,'LLM Stats list of Model'!$B$2:$N1003,6,false) -> Qwen3-Next-80B-A3B-Base | H18: =R18 -> Qwen | I18: =VLOOKUP(H18,'Unique Organization'!C$2:D$13,2,FALSE) -> qwen | L18: =IFERROR(__xludf.DUMMYFUNCTION("""COMPUTED_VALUE"""),"Nemotron") -> Nemotron | M18: =IFERROR(__xludf.DUMMYFUNCTION("""COMPUTED_VALUE"""),3.0) -> 3 | O18: Qwen3 Next | P18: =IFERROR(__xludf.DUMMYFUNCTION("""COMPUTED_VALUE"""),"Qwen") -> Qwen | Q18: Qwen | R18: =IFERROR(__xludf.DUMMYFUNCTION("""COMPUTED_VALUE"""),"Qwen") -> Qwen | S18: =IFERROR(__xludf.DUMMYFUNCTION("""COMPUTED_VALUE"""),"Other") -> Other | T18: =IFERROR(__xludf.DUMMYFUNCTION("""COMPUTED_VALUE"""),"Qwen") -> Qwen | U18: =IFERROR(__xludf.DUMMYFUNCTION("""COMPUTED_VALUE"""),"Other") -> Other | V18: =IFERROR(__xludf.DUMMYFUNCTION("""COMPUTED_VALUE"""),"Other") -> Other | W18: =IFERROR(__xludf.DUMMYFUNCTION("""COMPUTED_VALUE"""),"Other") -> Other | X18: =IFERROR(__xludf.DUMMYFUNCTION("""COMPUTED_VALUE"""),"Other") -> Other | Y18: =IFERROR(__xludf.DUMMYFUNCTION("""COMPUTED_VALUE"""),"Other") -> Other | Z18: =IFERROR(__xludf.DUMMYFUNCTION("""COMPUTED_VALUE"""),"Other") -> Other | AA18: =IFERROR(__xludf.DUMMYFUNCTION("""COMPUTED_VALUE"""),"Other") -> Other | AB18: =IFERROR(__xludf.DUMMYFUNCTION("""COMPUTED_VALUE"""),"Other") -> Other | ... AD18: =IFERROR(__xludf.DUMMYFUNCTION("""COMPUTED_VALUE"""),"Other") -> Other
A19: =O19 -> Olmo 3 | H19: =R19 | L19: =IFERROR(__xludf.DUMMYFUNCTION("""COMPUTED_VALUE"""),"Olmo") -> Olmo | M19: =IFERROR(__xludf.DUMMYFUNCTION("""COMPUTED_VALUE"""),1.0) -> 1 | O19: Olmo 3 | P19: =IFERROR(__xludf.DUMMYFUNCTION("""COMPUTED_VALUE"""),"Other") -> Other | Q19: Other | S19: =IFERROR(__xludf.DUMMYFUNCTION("""COMPUTED_VALUE"""),"Other") -> Other | T19: =IFERROR(__xludf.DUMMYFUNCTION("""COMPUTED_VALUE"""),"Other") -> Other | U19: =IFERROR(__xludf.DUMMYFUNCTION("""COMPUTED_VALUE"""),"Other") -> Other | V19: =IFERROR(__xludf.DUMMYFUNCTION("""COMPUTED_VALUE"""),"Other") -> Other | W19: =IFERROR(__xludf.DUMMYFUNCTION("""COMPUTED_VALUE"""),"Other") -> Other | X19: =IFERROR(__xludf.DUMMYFUNCTION("""COMPUTED_VALUE"""),"Other") -> Other | Y19: =IFERROR(__xludf.DUMMYFUNCTION("""COMPUTED_VALUE"""),"Other") -> Other | Z19: =IFERROR(__xludf.DUMMYFUNCTION("""COMPUTED_VALUE"""),"Other") -> Other | ... AD19: =IFERROR(__xludf.DUMMYFUNCTION("""COMPUTED_VALUE"""),"Other") -> Other
A20: =O20 -> olmOCR 2 | H20: =R20 | L20: =IFERROR(__xludf.DUMMYFUNCTION("""COMPUTED_VALUE"""),"Qwen3") -> Qwen3 | M20: =IFERROR(__xludf.DUMMYFUNCTION("""COMPUTED_VALUE"""),3.0) -> 3 | O20: olmOCR 2 | P20: =IFERROR(__xludf.DUMMYFUNCTION("""COMPUTED_VALUE"""),"Other") -> Other | Q20: Other | S20: =IFERROR(__xludf.DUMMYFUNCTION("""COMPUTED_VALUE"""),"Other") -> Other | T20: =IFERROR(__xludf.DUMMYFUNCTION("""COMPUTED_VALUE"""),"Other") -> Other | U20: =IFERROR(__xludf.DUMMYFUNCTION("""COMPUTED_VALUE"""),"Other") -> Other | V20: =IFERROR(__xludf.DUMMYFUNCTION("""COMPUTED_VALUE"""),"Other") -> Other | W20: =IFERROR(__xludf.DUMMYFUNCTION("""COMPUTED_VALUE"""),"Other") -> Other | X20: =IFERROR(__xludf.DUMMYFUNCTION("""COMPUTED_VALUE"""),"Other") -> Other | Y20: =IFERROR(__xludf.DUMMYFUNCTION("""COMPUTED_VALUE"""),"Other") -> Other | Z20: =IFERROR(__xludf.DUMMYFUNCTION("""COMPUTED_VALUE"""),"Other") -> Other | ... AD20: =IFERROR(__xludf.DUMMYFUNCTION("""COMPUTED_VALUE"""),"Other") -> Other
A21: =O21 -> minimax-m2 | H21: =R21 | L21: =IFERROR(__xludf.DUMMYFUNCTION("""COMPUTED_VALUE"""),"Qwen3-Coder") -> Qwen3-Coder | M21: =IFERROR(__xludf.DUMMYFUNCTION("""COMPUTED_VALUE"""),1.0) -> 1 | O21: minimax-m2 | P21: =IFERROR(__xludf.DUMMYFUNCTION("""COMPUTED_VALUE"""),"Other") -> Other | Q21: Other | S21: =IFERROR(__xludf.DUMMYFUNCTION("""COMPUTED_VALUE"""),"Other") -> Other | T21: =IFERROR(__xludf.DUMMYFUNCTION("""COMPUTED_VALUE"""),"Other") -> Other | U21: =IFERROR(__xludf.DUMMYFUNCTION("""COMPUTED_VALUE"""),"Other") -> Other | V21: =IFERROR(__xludf.DUMMYFUNCTION("""COMPUTED_VALUE"""),"Other") -> Other | W21: =IFERROR(__xludf.DUMMYFUNCTION("""COMPUTED_VALUE"""),"Other") -> Other | X21: =IFERROR(__xludf.DUMMYFUNCTION("""COMPUTED_VALUE"""),"Other") -> Other | Y21: =IFERROR(__xludf.DUMMYFUNCTION("""COMPUTED_VALUE"""),"Other") -> Other | Z21: =IFERROR(__xludf.DUMMYFUNCTION("""COMPUTED_VALUE"""),"Other") -> Other | ... AD21: =IFERROR(__xludf.DUMMYFUNCTION("""COMPUTED_VALUE"""),"Other") -> Other
A22: =O22 -> gpt-oss-safeguard | D22: https://llm-stats.com/models/gpt-oss-20b | F22: =VLOOKUP($D22,'LLM Stats list of Model'!$B$2:$N1003,4,false) | G22: =VLOOKUP($D22,'LLM Stats list of Model'!$B$2:$N1003,6,false) -> GPT OSS 20B | H22: =R22 -> GPT | I22: =VLOOKUP(H22,'Unique Organization'!C$2:D$13,2,FALSE) -> openai | L22: =IFERROR(__xludf.DUMMYFUNCTION("""COMPUTED_VALUE"""),"Qwen3-Coder-Next") -> Qwen3-Coder-Next | M22: =IFERROR(__xludf.DUMMYFUNCTION("""COMPUTED_VALUE"""),1.0) -> 1 | O22: gpt-oss-safeguard | P22: =IFERROR(__xludf.DUMMYFUNCTION("""COMPUTED_VALUE"""),"Other") -> Other | Q22: Other | R22: =IFERROR(__xludf.DUMMYFUNCTION("""COMPUTED_VALUE"""),"GPT") -> GPT | S22: =IFERROR(__xludf.DUMMYFUNCTION("""COMPUTED_VALUE"""),"Other") -> Other | T22: =IFERROR(__xludf.DUMMYFUNCTION("""COMPUTED_VALUE"""),"Other") -> Other | U22: =IFERROR(__xludf.DUMMYFUNCTION("""COMPUTED_VALUE"""),"Other") -> Other | V22: =IFERROR(__xludf.DUMMYFUNCTION("""COMPUTED_VALUE"""),"Other") -> Other | W22: =IFERROR(__xludf.DUMMYFUNCTION("""COMPUTED_VALUE"""),"Other") -> Other | X22: =IFERROR(__xludf.DUMMYFUNCTION("""COMPUTED_VALUE"""),"Other") -> Other | Y22: =IFERROR(__xludf.DUMMYFUNCTION("""COMPUTED_VALUE"""),"Other") -> Other | Z22: =IFERROR(__xludf.DUMMYFUNCTION("""COMPUTED_VALUE"""),"Other") -> Other | ... AC22: =IFERROR(__xludf.DUMMYFUNCTION("""COMPUTED_VALUE"""),"Other") -> Other | AD22: =IFERROR(__xludf.DUMMYFUNCTION("""COMPUTED_VALUE"""),"GPT") -> GPT
A23: =O23 -> Qwen3-VL | D23: https://llm-stats.com/models/qwen3-vl-4b-instruct | F23: =VLOOKUP($D23,'LLM Stats list of Model'!$B$2:$N1003,4,false) -> 2 | G23: =VLOOKUP($D23,'LLM Stats list of Model'!$B$2:$N1003,6,false) -> Qwen3 VL 4B Instruct | H23: =R23 -> Qwen | I23: =VLOOKUP(H23,'Unique Organization'!C$2:D$13,2,FALSE) -> qwen | L23: =IFERROR(__xludf.DUMMYFUNCTION("""COMPUTED_VALUE"""),"Qwen3-VL") -> Qwen3-VL | M23: =IFERROR(__xludf.DUMMYFUNCTION("""COMPUTED_VALUE"""),1.0) -> 1 | O23: Qwen3-VL | P23: =IFERROR(__xludf.DUMMYFUNCTION("""COMPUTED_VALUE"""),"Qwen") -> Qwen | Q23: Qwen | R23: =IFERROR(__xludf.DUMMYFUNCTION("""COMPUTED_VALUE"""),"Qwen") -> Qwen | S23: =IFERROR(__xludf.DUMMYFUNCTION("""COMPUTED_VALUE"""),"Other") -> Other | T23: =IFERROR(__xludf.DUMMYFUNCTION("""COMPUTED_VALUE"""),"Qwen") -> Qwen | U23: =IFERROR(__xludf.DUMMYFUNCTION("""COMPUTED_VALUE"""),"Other") -> Other | V23: =IFERROR(__xludf.DUMMYFUNCTION("""COMPUTED_VALUE"""),"Other") -> Other | W23: =IFERROR(__xludf.DUMMYFUNCTION("""COMPUTED_VALUE"""),"Other") -> Other | X23: =IFERROR(__xludf.DUMMYFUNCTION("""COMPUTED_VALUE"""),"Other") -> Other | Y23: =IFERROR(__xludf.DUMMYFUNCTION("""COMPUTED_VALUE"""),"Other") -> Other | Z23: =IFERROR(__xludf.DUMMYFUNCTION("""COMPUTED_VALUE"""),"Other") -> Other | AA23: =IFERROR(__xludf.DUMMYFUNCTION("""COMPUTED_VALUE"""),"Other") -> Other | AB23: =IFERROR(__xludf.DUMMYFUNCTION("""COMPUTED_VALUE"""),"Other") -> Other | ... AD23: =IFERROR(__xludf.DUMMYFUNCTION("""COMPUTED_VALUE"""),"Other") -> Other
A24: =O24 -> Granite 4.0 | H24: =R24 | L24: =IFERROR(__xludf.DUMMYFUNCTION("""COMPUTED_VALUE"""),"Qwen3.5") -> Qwen3.5 | M24: =IFERROR(__xludf.DUMMYFUNCTION("""COMPUTED_VALUE"""),1.0) -> 1 | O24: Granite 4.0 | P24: =IFERROR(__xludf.DUMMYFUNCTION("""COMPUTED_VALUE"""),"Other") -> Other | Q24: Other | S24: =IFERROR(__xludf.DUMMYFUNCTION("""COMPUTED_VALUE"""),"Other") -> Other | T24: =IFERROR(__xludf.DUMMYFUNCTION("""COMPUTED_VALUE"""),"Other") -> Other | U24: =IFERROR(__xludf.DUMMYFUNCTION("""COMPUTED_VALUE"""),"Other") -> Other | V24: =IFERROR(__xludf.DUMMYFUNCTION("""COMPUTED_VALUE"""),"Other") -> Other | W24: =IFERROR(__xludf.DUMMYFUNCTION("""COMPUTED_VALUE"""),"Other") -> Other | X24: =IFERROR(__xludf.DUMMYFUNCTION("""COMPUTED_VALUE"""),"Other") -> Other | Y24: =IFERROR(__xludf.DUMMYFUNCTION("""COMPUTED_VALUE"""),"Other") -> Other | Z24: =IFERROR(__xludf.DUMMYFUNCTION("""COMPUTED_VALUE"""),"Other") -> Other | ... AD24: =IFERROR(__xludf.DUMMYFUNCTION("""COMPUTED_VALUE"""),"Other") -> Other
A25: =O25 -> seed-oss | H25: =R25 | L25: =IFERROR(__xludf.DUMMYFUNCTION("""COMPUTED_VALUE"""),"Qwen3.6") -> Qwen3.6 | M25: =IFERROR(__xludf.DUMMYFUNCTION("""COMPUTED_VALUE"""),1.0) -> 1 | O25: seed-oss | P25: =IFERROR(__xludf.DUMMYFUNCTION("""COMPUTED_VALUE"""),"Other") -> Other | Q25: Other | S25: =IFERROR(__xludf.DUMMYFUNCTION("""COMPUTED_VALUE"""),"Other") -> Other | T25: =IFERROR(__xludf.DUMMYFUNCTION("""COMPUTED_VALUE"""),"Other") -> Other | U25: =IFERROR(__xludf.DUMMYFUNCTION("""COMPUTED_VALUE"""),"Other") -> Other | V25: =IFERROR(__xludf.DUMMYFUNCTION("""COMPUTED_VALUE"""),"Other") -> Other | W25: =IFERROR(__xludf.DUMMYFUNCTION("""COMPUTED_VALUE"""),"Other") -> Other | X25: =IFERROR(__xludf.DUMMYFUNCTION("""COMPUTED_VALUE"""),"Other") -> Other | Y25: =IFERROR(__xludf.DUMMYFUNCTION("""COMPUTED_VALUE"""),"Other") -> Other | Z25: =IFERROR(__xludf.DUMMYFUNCTION("""COMPUTED_VALUE"""),"Other") -> Other | ... AD25: =IFERROR(__xludf.DUMMYFUNCTION("""COMPUTED_VALUE"""),"Other") -> Other
A26: =O26 -> Qwen3 | D26: https://llm-stats.com/models/qwen3-32b | F26: =VLOOKUP($D26,'LLM Stats list of Model'!$B$2:$N1003,4,false) -> 2 | G26: =VLOOKUP($D26,'LLM Stats list of Model'!$B$2:$N1003,6,false) -> Qwen3 32B | H26: =R26 -> Qwen | I26: =VLOOKUP(H26,'Unique Organization'!C$2:D$13,2,FALSE) -> qwen | L26: =IFERROR(__xludf.DUMMYFUNCTION("""COMPUTED_VALUE"""),"Rnj-1") -> Rnj-1 | M26: =IFERROR(__xludf.DUMMYFUNCTION("""COMPUTED_VALUE"""),1.0) -> 1 | O26: Qwen3 | P26: =IFERROR(__xludf.DUMMYFUNCTION("""COMPUTED_VALUE"""),"Qwen") -> Qwen | Q26: Qwen | R26: =IFERROR(__xludf.DUMMYFUNCTION("""COMPUTED_VALUE"""),"Qwen") -> Qwen | S26: =IFERROR(__xludf.DUMMYFUNCTION("""COMPUTED_VALUE"""),"Other") -> Other | T26: =IFERROR(__xludf.DUMMYFUNCTION("""COMPUTED_VALUE"""),"Qwen") -> Qwen | U26: =IFERROR(__xludf.DUMMYFUNCTION("""COMPUTED_VALUE"""),"Other") -> Other | V26: =IFERROR(__xludf.DUMMYFUNCTION("""COMPUTED_VALUE"""),"Other") -> Other | W26: =IFERROR(__xludf.DUMMYFUNCTION("""COMPUTED_VALUE"""),"Other") -> Other | X26: =IFERROR(__xludf.DUMMYFUNCTION("""COMPUTED_VALUE"""),"Other") -> Other | Y26: =IFERROR(__xludf.DUMMYFUNCTION("""COMPUTED_VALUE"""),"Other") -> Other | Z26: =IFERROR(__xludf.DUMMYFUNCTION("""COMPUTED_VALUE"""),"Other") -> Other | AA26: =IFERROR(__xludf.DUMMYFUNCTION("""COMPUTED_VALUE"""),"Other") -> Other | AB26: =IFERROR(__xludf.DUMMYFUNCTION("""COMPUTED_VALUE"""),"Other") -> Other | ... AD26: =IFERROR(__xludf.DUMMYFUNCTION("""COMPUTED_VALUE"""),"Other") -> Other
A27: =O27 -> gpt-oss | D27: https://llm-stats.com/models/gpt-oss-20b | F27: =VLOOKUP($D27,'LLM Stats list of Model'!$B$2:$N1003,4,false) | G27: =VLOOKUP($D27,'LLM Stats list of Model'!$B$2:$N1003,6,false) -> GPT OSS 20B | H27: =R27 -> GPT | I27: =VLOOKUP(H27,'Unique Organization'!C$2:D$13,2,FALSE) -> openai | L27: =IFERROR(__xludf.DUMMYFUNCTION("""COMPUTED_VALUE"""),"deepseek-r1") -> deepseek-r1 | M27: =IFERROR(__xludf.DUMMYFUNCTION("""COMPUTED_VALUE"""),1.0) -> 1 | O27: gpt-oss | P27: =IFERROR(__xludf.DUMMYFUNCTION("""COMPUTED_VALUE"""),"Other") -> Other | Q27: Other | R27: =IFERROR(__xludf.DUMMYFUNCTION("""COMPUTED_VALUE"""),"GPT") -> GPT | S27: =IFERROR(__xludf.DUMMYFUNCTION("""COMPUTED_VALUE"""),"Other") -> Other | T27: =IFERROR(__xludf.DUMMYFUNCTION("""COMPUTED_VALUE"""),"Other") -> Other | U27: =IFERROR(__xludf.DUMMYFUNCTION("""COMPUTED_VALUE"""),"Other") -> Other | V27: =IFERROR(__xludf.DUMMYFUNCTION("""COMPUTED_VALUE"""),"Other") -> Other | W27: =IFERROR(__xludf.DUMMYFUNCTION("""COMPUTED_VALUE"""),"Other") -> Other | X27: =IFERROR(__xludf.DUMMYFUNCTION("""COMPUTED_VALUE"""),"Other") -> Other | Y27: =IFERROR(__xludf.DUMMYFUNCTION("""COMPUTED_VALUE"""),"Other") -> Other | Z27: =IFERROR(__xludf.DUMMYFUNCTION("""COMPUTED_VALUE"""),"Other") -> Other | ... AC27: =IFERROR(__xludf.DUMMYFUNCTION("""COMPUTED_VALUE"""),"Other") -> Other | AD27: =IFERROR(__xludf.DUMMYFUNCTION("""COMPUTED_VALUE"""),"GPT") -> GPT
A28: =O28 -> Qwen3-Coder | D28: https://llm-stats.com/models/qwen3-coder | F28: =VLOOKUP($D28,'LLM Stats list of Model'!$B$2:$N1003,4,false) -> 2 | G28: =VLOOKUP($D28,'LLM Stats list of Model'!$B$2:$N1003,6,false) -> Qwen3-Coder | H28: =R28 -> Qwen | I28: =VLOOKUP(H28,'Unique Organization'!C$2:D$13,2,FALSE) -> qwen | L28: =IFERROR(__xludf.DUMMYFUNCTION("""COMPUTED_VALUE"""),"gemma-3") -> gemma-3 | M28: =IFERROR(__xludf.DUMMYFUNCTION("""COMPUTED_VALUE"""),1.0) -> 1 | O28: Qwen3-Coder | P28: =IFERROR(__xludf.DUMMYFUNCTION("""COMPUTED_VALUE"""),"Qwen") -> Qwen | Q28: Qwen | R28: =IFERROR(__xludf.DUMMYFUNCTION("""COMPUTED_VALUE"""),"Qwen") -> Qwen | S28: =IFERROR(__xludf.DUMMYFUNCTION("""COMPUTED_VALUE"""),"Other") -> Other | T28: =IFERROR(__xludf.DUMMYFUNCTION("""COMPUTED_VALUE"""),"Qwen") -> Qwen | U28: =IFERROR(__xludf.DUMMYFUNCTION("""COMPUTED_VALUE"""),"Other") -> Other | V28: =IFERROR(__xludf.DUMMYFUNCTION("""COMPUTED_VALUE"""),"Other") -> Other | W28: =IFERROR(__xludf.DUMMYFUNCTION("""COMPUTED_VALUE"""),"Other") -> Other | X28: =IFERROR(__xludf.DUMMYFUNCTION("""COMPUTED_VALUE"""),"Other") -> Other | Y28: =IFERROR(__xludf.DUMMYFUNCTION("""COMPUTED_VALUE"""),"Other") -> Other | Z28: =IFERROR(__xludf.DUMMYFUNCTION("""COMPUTED_VALUE"""),"Other") -> Other | AA28: =IFERROR(__xludf.DUMMYFUNCTION("""COMPUTED_VALUE"""),"Other") -> Other | AB28: =IFERROR(__xludf.DUMMYFUNCTION("""COMPUTED_VALUE"""),"Other") -> Other | ... AD28: =IFERROR(__xludf.DUMMYFUNCTION("""COMPUTED_VALUE"""),"Other") -> Other
A29: =O29 -> Ernie-4.5 | H29: =R29 | L29: =IFERROR(__xludf.DUMMYFUNCTION("""COMPUTED_VALUE"""),"gemma-3n") -> gemma-3n | M29: =IFERROR(__xludf.DUMMYFUNCTION("""COMPUTED_VALUE"""),1.0) -> 1 | O29: Ernie-4.5 | P29: =IFERROR(__xludf.DUMMYFUNCTION("""COMPUTED_VALUE"""),"Other") -> Other | Q29: Other | S29: =IFERROR(__xludf.DUMMYFUNCTION("""COMPUTED_VALUE"""),"Other") -> Other | T29: =IFERROR(__xludf.DUMMYFUNCTION("""COMPUTED_VALUE"""),"Other") -> Other | U29: =IFERROR(__xludf.DUMMYFUNCTION("""COMPUTED_VALUE"""),"Other") -> Other | V29: =IFERROR(__xludf.DUMMYFUNCTION("""COMPUTED_VALUE"""),"Other") -> Other | W29: =IFERROR(__xludf.DUMMYFUNCTION("""COMPUTED_VALUE"""),"Other") -> Other | X29: =IFERROR(__xludf.DUMMYFUNCTION("""COMPUTED_VALUE"""),"Other") -> Other | Y29: =IFERROR(__xludf.DUMMYFUNCTION("""COMPUTED_VALUE"""),"Other") -> Other | Z29: =IFERROR(__xludf.DUMMYFUNCTION("""COMPUTED_VALUE"""),"Other") -> Other | ... AD29: =IFERROR(__xludf.DUMMYFUNCTION("""COMPUTED_VALUE"""),"Other") -> Other
A30: =O30 -> LFM2 | H30: =R30 | L30: =IFERROR(__xludf.DUMMYFUNCTION("""COMPUTED_VALUE"""),"gpt-oss") -> gpt-oss | M30: =IFERROR(__xludf.DUMMYFUNCTION("""COMPUTED_VALUE"""),1.0) -> 1 | O30: LFM2 | P30: =IFERROR(__xludf.DUMMYFUNCTION("""COMPUTED_VALUE"""),"Other") -> Other | Q30: Other | S30: =IFERROR(__xludf.DUMMYFUNCTION("""COMPUTED_VALUE"""),"Other") -> Other | T30: =IFERROR(__xludf.DUMMYFUNCTION("""COMPUTED_VALUE"""),"Other") -> Other | U30: =IFERROR(__xludf.DUMMYFUNCTION("""COMPUTED_VALUE"""),"Other") -> Other | V30: =IFERROR(__xludf.DUMMYFUNCTION("""COMPUTED_VALUE"""),"Other") -> Other | W30: =IFERROR(__xludf.DUMMYFUNCTION("""COMPUTED_VALUE"""),"Other") -> Other | X30: =IFERROR(__xludf.DUMMYFUNCTION("""COMPUTED_VALUE"""),"Other") -> Other | Y30: =IFERROR(__xludf.DUMMYFUNCTION("""COMPUTED_VALUE"""),"Other") -> Other | Z30: =IFERROR(__xludf.DUMMYFUNCTION("""COMPUTED_VALUE"""),"Other") -> Other | ... AD30: =IFERROR(__xludf.DUMMYFUNCTION("""COMPUTED_VALUE"""),"Other") -> Other
A31: =O31 -> Devstral | D31: https://llm-stats.com/models/devstral-small-2507 | F31: =VLOOKUP($D31,'LLM Stats list of Model'!$B$2:$N1003,4,false) | G31: =VLOOKUP($D31,'LLM Stats list of Model'!$B$2:$N1003,6,false) -> Devstral Small 1.1 | H31: =R31 -> Devstral | I31: =VLOOKUP(H31,'Unique Organization'!C$2:D$13,2,FALSE) -> mistral | L31: =IFERROR(__xludf.DUMMYFUNCTION("""COMPUTED_VALUE"""),"gpt-oss-safeguard") -> gpt-oss-safeguard | M31: =IFERROR(__xludf.DUMMYFUNCTION("""COMPUTED_VALUE"""),1.0) -> 1 | O31: Devstral | P31: =IFERROR(__xludf.DUMMYFUNCTION("""COMPUTED_VALUE"""),"Other") -> Other | Q31: Other | R31: =IFERROR(__xludf.DUMMYFUNCTION("""COMPUTED_VALUE"""),"Devstral") -> Devstral | S31: =IFERROR(__xludf.DUMMYFUNCTION("""COMPUTED_VALUE"""),"Other") -> Other | T31: =IFERROR(__xludf.DUMMYFUNCTION("""COMPUTED_VALUE"""),"Other") -> Other | U31: =IFERROR(__xludf.DUMMYFUNCTION("""COMPUTED_VALUE"""),"Other") -> Other | V31: =IFERROR(__xludf.DUMMYFUNCTION("""COMPUTED_VALUE"""),"Other") -> Other | W31: =IFERROR(__xludf.DUMMYFUNCTION("""COMPUTED_VALUE"""),"Other") -> Other | X31: =IFERROR(__xludf.DUMMYFUNCTION("""COMPUTED_VALUE"""),"Other") -> Other | Y31: =IFERROR(__xludf.DUMMYFUNCTION("""COMPUTED_VALUE"""),"Other") -> Other | Z31: =IFERROR(__xludf.DUMMYFUNCTION("""COMPUTED_VALUE"""),"Other") -> Other | AA31: =IFERROR(__xludf.DUMMYFUNCTION("""COMPUTED_VALUE"""),"Other") -> Other | AB31: =IFERROR(__xludf.DUMMYFUNCTION("""COMPUTED_VALUE"""),"Devstral") -> Devstral | AC31: =IFERROR(__xludf.DUMMYFUNCTION("""COMPUTED_VALUE"""),"Other") -> Other | AD31: =IFERROR(__xludf.DUMMYFUNCTION("""COMPUTED_VALUE"""),"Other") -> Other
A32: =O32 -> gemma-3n | D32: https://llm-stats.com/models/gemma-3n-e2b | F32: =VLOOKUP($D32,'LLM Stats list of Model'!$B$2:$N1003,4,false) | G32: =VLOOKUP($D32,'LLM Stats list of Model'!$B$2:$N1003,6,false) -> Gemma 3n E2B | H32: =R32 -> Gemma | I32: =VLOOKUP(H32,'Unique Organization'!C$2:D$13,2,FALSE) -> google | L32: =IFERROR(__xludf.DUMMYFUNCTION("""COMPUTED_VALUE"""),"minimax-m2") -> minimax-m2 | M32: =IFERROR(__xludf.DUMMYFUNCTION("""COMPUTED_VALUE"""),1.0) -> 1 | O32: gemma-3n | P32: =IFERROR(__xludf.DUMMYFUNCTION("""COMPUTED_VALUE"""),"Gemma") -> Gemma | Q32: Other | R32: =IFERROR(__xludf.DUMMYFUNCTION("""COMPUTED_VALUE"""),"Gemma") -> Gemma | S32: =IFERROR(__xludf.DUMMYFUNCTION("""COMPUTED_VALUE"""),"Other") -> Other | T32: =IFERROR(__xludf.DUMMYFUNCTION("""COMPUTED_VALUE"""),"Other") -> Other | U32: =IFERROR(__xludf.DUMMYFUNCTION("""COMPUTED_VALUE"""),"Gemma") -> Gemma | V32: =IFERROR(__xludf.DUMMYFUNCTION("""COMPUTED_VALUE"""),"Other") -> Other | W32: =IFERROR(__xludf.DUMMYFUNCTION("""COMPUTED_VALUE"""),"Other") -> Other | X32: =IFERROR(__xludf.DUMMYFUNCTION("""COMPUTED_VALUE"""),"Other") -> Other | Y32: =IFERROR(__xludf.DUMMYFUNCTION("""COMPUTED_VALUE"""),"Other") -> Other | Z32: =IFERROR(__xludf.DUMMYFUNCTION("""COMPUTED_VALUE"""),"Other") -> Other | AA32: =IFERROR(__xludf.DUMMYFUNCTION("""COMPUTED_VALUE"""),"Other") -> Other | AB32: =IFERROR(__xludf.DUMMYFUNCTION("""COMPUTED_VALUE"""),"Other") -> Other | AC32: =IFERROR(__xludf.DUMMYFUNCTION("""COMPUTED_VALUE"""),"Other") -> Other | AD32: =IFERROR(__xludf.DUMMYFUNCTION("""COMPUTED_VALUE"""),"Other") -> Other
A33: =O33 -> Mistral Small | D33: https://llm-stats.com/models/mistral-small-latest | F33: =VLOOKUP($D33,'LLM Stats list of Model'!$B$2:$N1003,4,false) | G33: =VLOOKUP($D33,'LLM Stats list of Model'!$B$2:$N1003,6,false) -> Mistral Small 4 | H33: =R33 -> Mistral | I33: =VLOOKUP(H33,'Unique Organization'!C$2:D$13,2,FALSE) -> mistral | L33: =IFERROR(__xludf.DUMMYFUNCTION("""COMPUTED_VALUE"""),"mistral-nemo") -> mistral-nemo | M33: =IFERROR(__xludf.DUMMYFUNCTION("""COMPUTED_VALUE"""),1.0) -> 1 | O33: Mistral Small | P33: =IFERROR(__xludf.DUMMYFUNCTION("""COMPUTED_VALUE"""),"Other") -> Other | Q33: Other | R33: =IFERROR(__xludf.DUMMYFUNCTION("""COMPUTED_VALUE"""),"Mistral") -> Mistral | S33: =IFERROR(__xludf.DUMMYFUNCTION("""COMPUTED_VALUE"""),"Other") -> Other | T33: =IFERROR(__xludf.DUMMYFUNCTION("""COMPUTED_VALUE"""),"Other") -> Other | U33: =IFERROR(__xludf.DUMMYFUNCTION("""COMPUTED_VALUE"""),"Other") -> Other | V33: =IFERROR(__xludf.DUMMYFUNCTION("""COMPUTED_VALUE"""),"Other") -> Other | W33: =IFERROR(__xludf.DUMMYFUNCTION("""COMPUTED_VALUE"""),"Other") -> Other | X33: =IFERROR(__xludf.DUMMYFUNCTION("""COMPUTED_VALUE"""),"Mistral") -> Mistral | Y33: =IFERROR(__xludf.DUMMYFUNCTION("""COMPUTED_VALUE"""),"Other") -> Other | Z33: =IFERROR(__xludf.DUMMYFUNCTION("""COMPUTED_VALUE"""),"Other") -> Other | AA33: =IFERROR(__xludf.DUMMYFUNCTION("""COMPUTED_VALUE"""),"Other") -> Other | AB33: =IFERROR(__xludf.DUMMYFUNCTION("""COMPUTED_VALUE"""),"Other") -> Other | AC33: =IFERROR(__xludf.DUMMYFUNCTION("""COMPUTED_VALUE"""),"Other") -> Other | AD33: =IFERROR(__xludf.DUMMYFUNCTION("""COMPUTED_VALUE"""),"Other") -> Other
